Connection established to iFast Server
New directory 20240819 created
Topolgy files copied from Gather server


The following table displays the elements with more than one entry in the combined toplogy files
NE_NAME
1170654_5GNB_CHNT_ACPFP_117065400    [Branchburg2, Southlake5]
1170654_5GNB_CHNT_AUPFP_117065410    [Branchburg2, Southlake5]
Name: USM, dtype: object
====================================


The following table displays the elements with more than one entry (NE_ID + USM) in the combined toplogy files
Empty DataFrame
Columns: [NE_UNIQUE_ID, NE_NAME, NE_TYPE, NE_VERSION, ENB_TYPE, CHANNEL_CARD, GNB_ID, REL_VERSION, Market, Region, Modified_Time]
Index: []


Combined Topolgy file created
Updating data beloging to {'Southlake2'}


Deleting {'Southlake2'} from network_topology table
Traceback (most recent call last):
  File "/home/sieluser/Topology/Topology.py", line 182, in <module>
    main()
  File "/home/sieluser/Topology/Topology.py", line 163, in main
    cur.execute(usm_del_query)
  File "/usr/local/lib/python3.6/site-packages/pymysql/cursors.py", line 148, in execute
    result = self._query(query)
  File "/usr/local/lib/python3.6/site-packages/pymysql/cursors.py", line 310, in _query
    conn.query(q)
  File "/usr/local/lib/python3.6/site-packages/pymysql/connections.py", line 548, in query
    self._affected_rows = self._read_query_result(unbuffered=unbuffered)
  File "/usr/local/lib/python3.6/site-packages/pymysql/connections.py", line 775, in _read_query_result
    result.read()
  File "/usr/local/lib/python3.6/site-packages/pymysql/connections.py", line 1156, in read
    first_packet = self.connection._read_packet()
  File "/usr/local/lib/python3.6/site-packages/pymysql/connections.py", line 725, in _read_packet
    packet.raise_for_error()
  File "/usr/local/lib/python3.6/site-packages/pymysql/protocol.py", line 221, in raise_for_error
    err.raise_mysql_exception(self._data)
  File "/usr/local/lib/python3.6/site-packages/pymysql/err.py", line 143, in raise_mysql_exception
    raise errorclass(errno, errval)
pymysql.err.ProgrammingError: (1064, "You have an error in your SQL syntax; check the manual that corresponds to your MySQL server version for the right syntax to use near ')' at line 1")
